Workbook

Sheet Mode d'emploi
A1: Dossier défis – PhotoCoque Lab (mini-usine de coques personnalisées)
A2: Projet d'organisation industrielle · BTS ATI 2 · 5 équipes de 3 apprentis
B5: Contexte : le kiosque Photomaton personnalise une coque de smartphone (plus de 60 modèles, 15 €) avec la photo choisie par le client et la livre en 3 minutes. Nous passons du kiosque à une MINI-USINE de 6 postes qui fabrique ces coques à la demande (voir l'onglet « Ligne PhotoCoque »). Chaque équipe (3 apprentis) traite UN défi sur cette mini-usine et le présente en fin de projet. Les 5 défis sont décrits dans l'onglet « Les 5 défis ». Chaque équipe remplit son onglet « Équipe n ». Les données viennent de la supervision web (un onglet par défi) et du journal CSV téléchargeable.
B6: Code couleur : cellules JAUNES = à remplir ; texte bleu en italique = exemple à remplacer ; bandeaux foncés = titres (ne pas modifier).
B7: Outils : supervision web (index.html) · kiosque client (kiosque.html) · simulateur Node-RED · Tab5 sur la ligne réelle · journal CSV (ouvrir dans Excel).
A8: Méthode | B8: Analyse fonctionnelle du besoin (méthode APTE) :
A9: • Bête à cornes | B9: exprime le BESOIN : à qui/à quoi le projet rend-il service, sur quoi agit-il, dans quel but.
A10: • Diagramme pieuvre | B10: relie le système étudié à son milieu extérieur (EME). FP = fonction principale (relie 2 EME en passant par le système). FC = fonction contrainte (relie le système à 1 EME).
A11: • Organigramme | B11: répartit les 3 rôles de l'équipe : chef de projet, responsable technique, responsable qualité & communication.
A13: Contenu d'un onglet équipe | B13: 1) Identité + organigramme · 2) Bête à cornes · 3) Diagramme pieuvre · 4) Objectifs mesurables · 5) Planning et répartition · 6) Grille d'évaluation /20.
A14: Règle | B14: chaque objectif doit être MESURABLE (valeur de départ, valeur cible). Relever l'état de départ dès la 1re séance pour prouver le gain.

Sheet Les 5 défis
A1: Les 5 défis
A2: Un défi par équipe — attribué par le formateur
B4: N° | C4: Défi | D4: Domaine | E4: Problème de départ | F4: Objectif principal | G4: Indicateur clé | H4: Données / outils fournis
B5: 1 | C5: Équilibrage de la ligne | D5: Organisation industrielle | E5: Le poste 4 (Pose robot & marouflage, 75 s) est plus lent que le takt (60 s) : la mini-usine ne tient pas la demande de 420 coques par jour. | F5: Équilibrer les temps de cycle des 6 postes pour passer sous le takt et atteindre une capacité ≥ 420 coques/jour. | G5: Écart temps de cycle / takt par poste ; capacité (coques/jour) | H5: Supervision onglet « Défi 1 » (diagramme de charge, takt, goulot) ; réglages temps de cycle et machines ; journal CSV (PIECE)
B6: 2 | C6: Réduction des en-cours (Kanban) | D6: Organisation industrielle | E6: Les stickers imprimés s'accumulent devant le robot de pose : le délai de traversée se compte en heures, loin de la promesse « coque prête en quelques minutes ». | F6: Dimensionner les boucles Kanban (stock max devant chaque poste, CONWIP) et réduire l'en-cours sans perdre de débit. | G6: En-cours moyen (WIP) ; délai de traversée (loi de Little) ; débit (coques/h) | H6: Supervision onglet « Défi 2 » (en-cours par poste, Little) ; réglages Kanban et CONWIP ; journal CSV (COMMANDE, LIVRAISON)
B7: 3 | C7: Mesure et amélioration du TRS | D7: Qualité / Organisation | E7: Le rendement réel de la mini-usine (TRS) n'est pas connu : pannes, attentes et coques NOK se cumulent. | F7: Calculer le TRS (D × P × Q), classer les pertes et réduire la perte principale. | G7: TRS (%) par poste et ligne ; Pareto des pertes (arrêts, cadence, non-qualité) | H7: Supervision onglet « Défi 3 » (TRS par poste, répartition des temps) ; journal CSV (ETAT, PIECE, QUALITE)
B8: 4 | C8: Plan de maintenance préventive | D8: Maintenance | E8: Des pannes répétées arrêtent l'imprimante (P2 : bourrage, buses, encre) et le robot de pose (P4 : ventouse, rouleau de marouflage, axe). | F8: Construire un plan de maintenance préventive (périodicité, seuils de vibration) à partir de l'historique des pannes. | G8: MTBF, MTTR, disponibilité ; périodicité préventive ; seuil d'alerte vibration | H8: Supervision onglet « Défi 4 » (pannes, MTBF/MTTR, vibrations, bouton maintenance) ; Tab5 maintenance (IMU) ; journal CSV (ETAT, VIBRATION)
B9: 5 | C9: Maîtrise de la qualité visuelle | D9: Qualité | E9: Des coques sortent NOK au contrôle caméra (P5) : visuel décalé, bulles, couleurs délavées, rayures. Chaque NOK est jetée et refaite. | F9: Réduire le taux de NOK sous 3 % et mettre en place une carte de contrôle p. | G9: Taux de NOK (%) ; Pareto des défauts ; carte p (p̄, LSC) | H9: Supervision onglet « Défi 5 » (Pareto, carte p, actions d'amélioration) ; Tab5 contrôle qualité ; journal CSV (QUALITE)
A11: Une équipe peut proposer une variante de son défi, à valider par le formateur. Tous les défis s'appuient sur la même mini-usine et les mêmes données MQTT / Node-RED. Le 6e défi (gestion des stocks de coques brutes) fait l'objet d'un TP spécifique.

Sheet Ligne PhotoCoque
A1: La mini-usine PhotoCoque — état de départ
A2: Valeurs de référence du simulateur (identiques à la supervision au démarrage). Relevez l'état de départ AVANT toute amélioration.
B4: Poste | C4: Désignation | D4: Stations de l'infographie | E4: Temps de cycle (s) | F4: Machines | G4: MTBF (s) | H4: MTTR (s) | I4: Pannes / défauts typiques
B5: P1 | C5: Alimentation & identification | D5: 1 Alimentation + 2 Identification | E5: 35 | F5: 1 | G5: 0 | H5: 0 | I5: —
B6: P2 | C6: Impression du visuel | D6: 3 Impression du sticker | E6: 50 | F6: 1 | G6: 5400 | H6: 420 | I6: bourrage papier, buses encrassées, encre vide
B7: P3 | C7: Découpe du sticker | D7: 4 Découpe / préparation | E7: 40 | F7: 1 | G7: 0 | H7: 0 | I7: rayures (convoyeur)
B8: P4 | C8: Pose robot & marouflage | D8: 5 Robot de pose + 6 Marouflage | E8: 75 | F8: 1 | G8: 3600 | H8: 600 | I8: ventouse usée, rouleau, axe robot ; défauts alignement et bulles
B9: P5 | C9: Contrôle qualité caméra | D9: 7 Contrôle qualité par caméra | E9: 30 | F9: 1 | G9: 0 | H9: 0 | I9: classe OK / NOK (alignement, bulles, couleur, rayures)
B10: P6 | C10: Emballage & sortie | D10: 8 Sortie / emballage | E10: 25 | F10: 1 | G10: 0 | H10: 0 | I10: —
B12: Données de demande et calculs
C13: Temps d'ouverture (s/jour) | E13: 25200 | F13: 7 h par jour
C14: Demande client (coques/jour) | E14: 420
C15: Takt (s) | E15: =E13/E14 -> 60 | F15: temps d'ouverture ÷ demande
C16: Contenu de travail total (s) | E16: =SUM(E5:E10) -> 255 | F16: somme des temps de cycle
C17: Temps de cycle du goulot (s) | E17: =MAX(E5:E10) -> 75
C18: Capacité théorique (coques/jour) | E18: =INT(E13/E17) -> 336 | F18: temps d'ouverture ÷ temps du goulot
C19: Nombre minimal de postes équilibrés | E19: =ROUNDUP(E16/E15,0) -> 5 | F19: contenu de travail ÷ takt (arrondi au supérieur)
C20: Défauts au contrôle (départ) | E20: 8,0 % | F20: alignement 3,5 % · bulles 2,5 % · couleur 1,2 % · rayures 0,8 %
C21: Seuils vibration (mm/s RMS) | E21: 4,0 / 6,0 | F21: alerte / danger
B23: Les cellules jaunes (ouverture, demande) et les temps de cycle peuvent être modifiés pour tester une hypothèse ; les calculs se mettent à jour.
B24: Correspondance avec l'infographie « Architecture d'une usine de coques de smartphone personnalisées » : 8 stations regroupées en 6 postes pour rester lisible.

Sheet Équipe 1
A1: Équipe 1 — Équilibrage de la ligne
A2: Domaine : Organisation industrielle
A4: Rappel du défi
B5: Problème de départ | C5: Le poste 4 (Pose robot & marouflage, 75 s) est plus lent que le takt (60 s) : la mini-usine ne tient pas la demande de 420 coques par jour.
B6: Objectif principal | C6: Équilibrer les temps de cycle des 6 postes pour passer sous le takt et atteindre une capacité ≥ 420 coques/jour.
B7: Indicateur clé | C7: Écart temps de cycle / takt par poste ; capacité (coques/jour)
B8: Données / outils fournis | C8: Supervision onglet « Défi 1 » (diagramme de charge, takt, goulot) ; réglages temps de cycle et machines ; journal CSV (PIECE)
A10: 1. Identité de l'équipe et organigramme
B11: Rôle | C11: Nom de l'apprenti | D11: Missions principales
B12: Chef de projet | D12: pilote, planning, lien formateur
B13: Responsable technique / méthodes | D13: mesures, solution, données
B14: Responsable qualité & communication | D14: indicateurs, dossier, soutenance
A15: Organigramme : chef de projet au-dessus, les deux autres au-dessous ; dessinez-le ou utilisez les trois rôles ci-dessus.
A17: 2. Bête à cornes (expression du besoin)
F18: À qui / à quoi le projet rend-il service ?
F20: Sur quoi / sur qui agit-il ?
F22: Dans quel but ? (le besoin)
B31: Pourquoi ce besoin existe-t-il ?
B32: Qu'est-ce qui pourrait le faire évoluer / disparaître ?
A34: 3. Diagramme pieuvre (analyse fonctionnelle)
F35: Système / produit étudié :
F38: Éléments du milieu extérieur (EME)
F39: Repère | G39: Désignation
F40: EME 1
F41: EME 2
F42: EME 3
F43: EME 4
F44: EME 5
F45: EME 6
B49: Fonctions (FP = relie 2 EME · FC = relie le système à 1 EME)
B50: Repère | C50: Type | D50: Énoncé de la fonction | F50: Niveau | G50: Flexibilité
B51: FP1 | C51: FP | D51: ex. permettre au responsable de production de suivre la mini-usine en temps réel | F51: temps d'affichage | G51: < 1 s | H51: ± 0,3 s
A59: 4. Objectifs mesurables
B60: Objectif | C60: Indicateur | D60: Valeur départ | E60: Valeur cible | F60: Comment on le mesure
A66: 5. Planning et répartition (une croix par tâche et par apprenti)
B67: Séance / jalon | C67: Objectif de la séance | D67: Tâches | F67: Tech. | G67: Qual.
B68: S1 – Cadrage | C68: État des lieux, mesures de départ, APTE
B69: S2 – Analyse | C69: Objectifs, solution, données
B70: S3 – Mise en œuvre | C70: Tester sur la mini-usine / le simulateur
B71: S4 – Bilan + soutenance | C71: Mesurer le gain, préparer la présentation
...

Sheet Équipe 2
A1: Équipe 2 — Réduction des en-cours (Kanban)
A2: Domaine : Organisation industrielle
A4: Rappel du défi
B5: Problème de départ | C5: Les stickers imprimés s'accumulent devant le robot de pose : le délai de traversée se compte en heures, loin de la promesse « coque prête en quelques minutes ».
B6: Objectif principal | C6: Dimensionner les boucles Kanban (stock max devant chaque poste, CONWIP) et réduire l'en-cours sans perdre de débit.
B7: Indicateur clé | C7: En-cours moyen (WIP) ; délai de traversée (loi de Little) ; débit (coques/h)
B8: Données / outils fournis | C8: Supervision onglet « Défi 2 » (en-cours par poste, Little) ; réglages Kanban et CONWIP ; journal CSV (COMMANDE, LIVRAISON)
A10: 1. Identité de l'équipe et organigramme
B11: Rôle | C11: Nom de l'apprenti | D11: Missions principales
B12: Chef de projet | D12: pilote, planning, lien formateur
B13: Responsable technique / méthodes | D13: mesures, solution, données
B14: Responsable qualité & communication | D14: indicateurs, dossier, soutenance
A15: Organigramme : chef de projet au-dessus, les deux autres au-dessous ; dessinez-le ou utilisez les trois rôles ci-dessus.
A17: 2. Bête à cornes (expression du besoin)
F18: À qui / à quoi le projet rend-il service ?
F20: Sur quoi / sur qui agit-il ?
F22: Dans quel but ? (le besoin)
B31: Pourquoi ce besoin existe-t-il ?
B32: Qu'est-ce qui pourrait le faire évoluer / disparaître ?
A34: 3. Diagramme pieuvre (analyse fonctionnelle)
F35: Système / produit étudié :
F38: Éléments du milieu extérieur (EME)
F39: Repère | G39: Désignation
F40: EME 1
F41: EME 2
F42: EME 3
F43: EME 4
F44: EME 5
F45: EME 6
B49: Fonctions (FP = relie 2 EME · FC = relie le système à 1 EME)
B50: Repère | C50: Type | D50: Énoncé de la fonction | F50: Niveau | G50: Flexibilité
B51: FP1 | C51: FP | D51: ex. permettre au responsable de production de suivre la mini-usine en temps réel | F51: temps d'affichage | G51: < 1 s | H51: ± 0,3 s
A59: 4. Objectifs mesurables
B60: Objectif | C60: Indicateur | D60: Valeur départ | E60: Valeur cible | F60: Comment on le mesure
A66: 5. Planning et répartition (une croix par tâche et par apprenti)
B67: Séance / jalon | C67: Objectif de la séance | D67: Tâches | F67: Tech. | G67: Qual.
B68: S1 – Cadrage | C68: État des lieux, mesures de départ, APTE
B69: S2 – Analyse | C69: Objectifs, solution, données
B70: S3 – Mise en œuvre | C70: Tester sur la mini-usine / le simulateur
B71: S4 – Bilan + soutenance | C71: Mesurer le gain, préparer la présentation
...

Sheet Équipe 3
A1: Équipe 3 — Mesure et amélioration du TRS
A2: Domaine : Qualité / Organisation
A4: Rappel du défi
B5: Problème de départ | C5: Le rendement réel de la mini-usine (TRS) n'est pas connu : pannes, attentes et coques NOK se cumulent.
B6: Objectif principal | C6: Calculer le TRS (D × P × Q), classer les pertes et réduire la perte principale.
B7: Indicateur clé | C7: TRS (%) par poste et ligne ; Pareto des pertes (arrêts, cadence, non-qualité)
B8: Données / outils fournis | C8: Supervision onglet « Défi 3 » (TRS par poste, répartition des temps) ; journal CSV (ETAT, PIECE, QUALITE)
A10: 1. Identité de l'équipe et organigramme
B11: Rôle | C11: Nom de l'apprenti | D11: Missions principales
B12: Chef de projet | D12: pilote, planning, lien formateur
B13: Responsable technique / méthodes | D13: mesures, solution, données
B14: Responsable qualité & communication | D14: indicateurs, dossier, soutenance
A15: Organigramme : chef de projet au-dessus, les deux autres au-dessous ; dessinez-le ou utilisez les trois rôles ci-dessus.
A17: 2. Bête à cornes (expression du besoin)
F18: À qui / à quoi le projet rend-il service ?
F20: Sur quoi / sur qui agit-il ?
F22: Dans quel but ? (le besoin)
B31: Pourquoi ce besoin existe-t-il ?
B32: Qu'est-ce qui pourrait le faire évoluer / disparaître ?
A34: 3. Diagramme pieuvre (analyse fonctionnelle)
F35: Système / produit étudié :
F38: Éléments du milieu extérieur (EME)
F39: Repère | G39: Désignation
F40: EME 1
F41: EME 2
F42: EME 3
F43: EME 4
F44: EME 5
F45: EME 6
B49: Fonctions (FP = relie 2 EME · FC = relie le système à 1 EME)
B50: Repère | C50: Type | D50: Énoncé de la fonction | F50: Niveau | G50: Flexibilité
B51: FP1 | C51: FP | D51: ex. permettre au responsable de production de suivre la mini-usine en temps réel | F51: temps d'affichage | G51: < 1 s | H51: ± 0,3 s
A59: 4. Objectifs mesurables
B60: Objectif | C60: Indicateur | D60: Valeur départ | E60: Valeur cible | F60: Comment on le mesure
A66: 5. Planning et répartition (une croix par tâche et par apprenti)
B67: Séance / jalon | C67: Objectif de la séance | D67: Tâches | F67: Tech. | G67: Qual.
B68: S1 – Cadrage | C68: État des lieux, mesures de départ, APTE
B69: S2 – Analyse | C69: Objectifs, solution, données
B70: S3 – Mise en œuvre | C70: Tester sur la mini-usine / le simulateur
B71: S4 – Bilan + soutenance | C71: Mesurer le gain, préparer la présentation
...

Sheet Équipe 4
A1: Équipe 4 — Plan de maintenance préventive
A2: Domaine : Maintenance
A4: Rappel du défi
B5: Problème de départ | C5: Des pannes répétées arrêtent l'imprimante (P2 : bourrage, buses, encre) et le robot de pose (P4 : ventouse, rouleau de marouflage, axe).
B6: Objectif principal | C6: Construire un plan de maintenance préventive (périodicité, seuils de vibration) à partir de l'historique des pannes.
B7: Indicateur clé | C7: MTBF, MTTR, disponibilité ; périodicité préventive ; seuil d'alerte vibration
B8: Données / outils fournis | C8: Supervision onglet « Défi 4 » (pannes, MTBF/MTTR, vibrations, bouton maintenance) ; Tab5 maintenance (IMU) ; journal CSV (ETAT, VIBRATION)
A10: 1. Identité de l'équipe et organigramme
B11: Rôle | C11: Nom de l'apprenti | D11: Missions principales
B12: Chef de projet | D12: pilote, planning, lien formateur
B13: Responsable technique / méthodes | D13: mesures, solution, données
B14: Responsable qualité & communication | D14: indicateurs, dossier, soutenance
A15: Organigramme : chef de projet au-dessus, les deux autres au-dessous ; dessinez-le ou utilisez les trois rôles ci-dessus.
A17: 2. Bête à cornes (expression du besoin)
F18: À qui / à quoi le projet rend-il service ?
F20: Sur quoi / sur qui agit-il ?
F22: Dans quel but ? (le besoin)
B31: Pourquoi ce besoin existe-t-il ?
B32: Qu'est-ce qui pourrait le faire évoluer / disparaître ?
A34: 3. Diagramme pieuvre (analyse fonctionnelle)
F35: Système / produit étudié :
F38: Éléments du milieu extérieur (EME)
F39: Repère | G39: Désignation
F40: EME 1
F41: EME 2
F42: EME 3
F43: EME 4
F44: EME 5
F45: EME 6
B49: Fonctions (FP = relie 2 EME · FC = relie le système à 1 EME)
B50: Repère | C50: Type | D50: Énoncé de la fonction | F50: Niveau | G50: Flexibilité
B51: FP1 | C51: FP | D51: ex. permettre au responsable de production de suivre la mini-usine en temps réel | F51: temps d'affichage | G51: < 1 s | H51: ± 0,3 s
A59: 4. Objectifs mesurables
B60: Objectif | C60: Indicateur | D60: Valeur départ | E60: Valeur cible | F60: Comment on le mesure
A66: 5. Planning et répartition (une croix par tâche et par apprenti)
B67: Séance / jalon | C67: Objectif de la séance | D67: Tâches | F67: Tech. | G67: Qual.
B68: S1 – Cadrage | C68: État des lieux, mesures de départ, APTE
B69: S2 – Analyse | C69: Objectifs, solution, données
B70: S3 – Mise en œuvre | C70: Tester sur la mini-usine / le simulateur
B71: S4 – Bilan + soutenance | C71: Mesurer le gain, préparer la présentation
...

Sheet Équipe 5
A1: Équipe 5 — Maîtrise de la qualité visuelle
A2: Domaine : Qualité
A4: Rappel du défi
B5: Problème de départ | C5: Des coques sortent NOK au contrôle caméra (P5) : visuel décalé, bulles, couleurs délavées, rayures. Chaque NOK est jetée et refaite.
B6: Objectif principal | C6: Réduire le taux de NOK sous 3 % et mettre en place une carte de contrôle p.
B7: Indicateur clé | C7: Taux de NOK (%) ; Pareto des défauts ; carte p (p̄, LSC)
B8: Données / outils fournis | C8: Supervision onglet « Défi 5 » (Pareto, carte p, actions d'amélioration) ; Tab5 contrôle qualité ; journal CSV (QUALITE)
A10: 1. Identité de l'équipe et organigramme
B11: Rôle | C11: Nom de l'apprenti | D11: Missions principales
B12: Chef de projet | D12: pilote, planning, lien formateur
B13: Responsable technique / méthodes | D13: mesures, solution, données
B14: Responsable qualité & communication | D14: indicateurs, dossier, soutenance
A15: Organigramme : chef de projet au-dessus, les deux autres au-dessous ; dessinez-le ou utilisez les trois rôles ci-dessus.
A17: 2. Bête à cornes (expression du besoin)
F18: À qui / à quoi le projet rend-il service ?
F20: Sur quoi / sur qui agit-il ?
F22: Dans quel but ? (le besoin)
B31: Pourquoi ce besoin existe-t-il ?
B32: Qu'est-ce qui pourrait le faire évoluer / disparaître ?
A34: 3. Diagramme pieuvre (analyse fonctionnelle)
F35: Système / produit étudié :
F38: Éléments du milieu extérieur (EME)
F39: Repère | G39: Désignation
F40: EME 1
F41: EME 2
F42: EME 3
F43: EME 4
F44: EME 5
F45: EME 6
B49: Fonctions (FP = relie 2 EME · FC = relie le système à 1 EME)
B50: Repère | C50: Type | D50: Énoncé de la fonction | F50: Niveau | G50: Flexibilité
B51: FP1 | C51: FP | D51: ex. permettre au responsable de production de suivre la mini-usine en temps réel | F51: temps d'affichage | G51: < 1 s | H51: ± 0,3 s
A59: 4. Objectifs mesurables
B60: Objectif | C60: Indicateur | D60: Valeur départ | E60: Valeur cible | F60: Comment on le mesure
A66: 5. Planning et répartition (une croix par tâche et par apprenti)
B67: Séance / jalon | C67: Objectif de la séance | D67: Tâches | F67: Tech. | G67: Qual.
B68: S1 – Cadrage | C68: État des lieux, mesures de départ, APTE
B69: S2 – Analyse | C69: Objectifs, solution, données
B70: S3 – Mise en œuvre | C70: Tester sur la mini-usine / le simulateur
B71: S4 – Bilan + soutenance | C71: Mesurer le gain, préparer la présentation
...

Sheet Synthèse
A1: Synthèse des 5 équipes
A2: Vue d'ensemble et notes
B4: Équipe | C4: Défi | D4: Domaine | E4: Note /20
B5: 1 | C5: Équilibrage de la ligne | D5: Organisation industrielle | E5: ='Équipe 1'!H81 -> 0
B6: 2 | C6: Réduction des en-cours (Kanban) | D6: Organisation industrielle | E6: ='Équipe 2'!H81 -> 0
B7: 3 | C7: Mesure et amélioration du TRS | D7: Qualité / Organisation | E7: ='Équipe 3'!H81 -> 0
B8: 4 | C8: Plan de maintenance préventive | D8: Maintenance | E8: ='Équipe 4'!H81 -> 0
B9: 5 | C9: Maîtrise de la qualité visuelle | D9: Qualité | E9: ='Équipe 5'!H81 -> 0
D10: Moyenne | E10: =AVERAGE(E5:E9) -> 0
